Workbook

Sheet Diagrama de Gantt - Estructura 
A1: ID | B1: WBS Nivel 2 / Tarea Nivel 3 | C1: Tipo | D1: Duración (Valor) | E1: Unidad (Días/Semanas/Meses) | F1: Responsable / Equipo | G1: 29/08/2026 | H1: Fecha Fin | I1: Estado | J1: Dependencia | K1: Entregables Asociados
A2: 1 | B2: INICIO Y PLANIFICACIÓN | C2: Entregable Nivel 2 | D2: 9 | E2: Días | F2: Ambos | G2: 46263 | H2: =IF(OR(C2="Hito",G2="",D2="",E2=""),"",IF(E2="Días",G2+D2-1,IF(E2="Semanas",G2+(D2*7)-1,IF(E2="Meses",EDATE(G2,D2)-1,"")))) -> 46271 | I2: Completado | J2: — | K2: Base de planificación
A3: 1.1 | B3: Definir metodología de trabajo | C3: Tarea Nivel 3 | D3: 1 | E3: Días | F3: Tú | G3: 46263 | H3: =IF(OR(C3="Hito",G3="",D3="",E3=""),"",IF(E3="Días",G3+D3-1,IF(E3="Semanas",G3+(D3*7)-1,IF(E3="Meses",EDATE(G3,D3)-1,"")))) -> 46263 | I3: Completado | J3: — | K3: Metodología acordada
A4: 1.2 | B4: Definir herramientas y repositorios | C4: Tarea Nivel 3 | D4: 1 | E4: Días | F4: Saul | G4: 46265 | H4: =IF(OR(C4="Hito",G4="",D4="",E4=""),"",IF(E4="Días",G4+D4-1,IF(E4="Semanas",G4+(D4*7)-1,IF(E4="Meses",EDATE(G4,D4)-1,"")))) -> 46265 | I4: Completado | J4: CC 1.1 | K4: Herramientas configuradas
A5: 1.3 | B5: Elaborar mapa de interesados | C5: Tarea Nivel 3 | D5: 1 | E5: Días | F5: Tú | G5: 46265 | H5: =IF(OR(C5="Hito",G5="",D5="",E5=""),"",IF(E5="Días",G5+D5-1,IF(E5="Semanas",G5+(D5*7)-1,IF(E5="Meses",EDATE(G5,D5)-1,"")))) -> 46265 | I5: Completado | J5: FC 1.1 | K5: Mapa de interesados
A6: 1.4 | B6: Revisar propósito, objetivos y alcance | C6: Tarea Nivel 3 | D6: 1 | E6: Días | F6: Ambos | G6: 46266 | H6: =IF(OR(C6="Hito",G6="",D6="",E6=""),"",IF(E6="Días",G6+D6-1,IF(E6="Semanas",G6+(D6*7)-1,IF(E6="Meses",EDATE(G6,D6)-1,"")))) -> 46266 | I6: Completado | J6: FC 1.1 | K6: Alcance validado
A7: 1.5 | B7: Definir esquema de comunicación del equipo | C7: Tarea Nivel 3 | D7: 1 | E7: Días | F7: Saul | G7: 46266 | H7: =IF(OR(C7="Hito",G7="",D7="",E7=""),"",IF(E7="Días",G7+D7-1,IF(E7="Semanas",G7+(D7*7)-1,IF(E7="Meses",EDATE(G7,D7)-1,"")))) -> 46266 | I7: Completado | J7: CC 1.3 | K7: Esquema de comunicación
A8: 1.6 | B8: Preparar estructura documental del proyecto | C8: Tarea Nivel 3 | D8: 1 | E8: Días | F8: Tú | G8: 46267 | H8: =IF(OR(C8="Hito",G8="",D8="",E8=""),"",IF(E8="Días",G8+D8-1,IF(E8="Semanas",G8+(D8*7)-1,IF(E8="Meses",EDATE(G8,D8)-1,"")))) -> 46267 | I8: Completado | J8: CC 1.4 | K8: Estructura documental
A9: 1.7 | B9: Preparar ambiente inicial de desarrollo | C9: Tarea Nivel 3 | D9: 2 | E9: Días | F9: Saul | G9: 46268 | H9: =IF(OR(C9="Hito",G9="",D9="",E9=""),"",IF(E9="Días",G9+D9-1,IF(E9="Semanas",G9+(D9*7)-1,IF(E9="Meses",EDATE(G9,D9)-1,"")))) -> 46269 | I9: Completado | J9: FC 1.2 | K9: Entorno inicial
A10: 1.8 | B10: Revisión de planificación inicial | C10: Tarea Nivel 3 | D10: 1 | E10: Días | F10: Ambos | G10: 46268 | H10: =IF(OR(C10="Hito",G10="",D10="",E10=""),"",IF(E10="Días",G10+D10-1,IF(E10="Semanas",G10+(D10*7)-1,IF(E10="Meses",EDATE(G10,D10)-1,"")))) -> 46268 | I10: Completado | J10: FF 1.5, 1.6, 1.7 | K10: Planificación inicial
A11: 2 | B11: REQUISITOS Y DISEÑO FUNCIONAL | C11: Entregable Nivel 2 | D11: 16 | E11: Días | F11: Ambos | G11: 46269 | H11: =IF(OR(C11="Hito",G11="",D11="",E11=""),"",IF(E11="Días",G11+D11-1,IF(E11="Semanas",G11+(D11*7)-1,IF(E11="Meses",EDATE(G11,D11)-1,"")))) -> 46284 | I11: En Proceso | J11: FC 1.8 | K11: Especificación funcional
A12: 2.1 | B12: Levantamiento de requisitos funcionales | C12: Tarea Nivel 3 | D12: 3 | E12: Días | F12: Tú | G12: 46269 | H12: =IF(OR(C12="Hito",G12="",D12="",E12=""),"",IF(E12="Días",G12+D12-1,IF(E12="Semanas",G12+(D12*7)-1,IF(E12="Meses",EDATE(G12,D12)-1,"")))) -> 46271 | I12: Completado | J12: FC 1.8 | K12: Requisitos funcionales
A13: 2.2 | B13: Levantamiento de requisitos no funcionales | C13: Tarea Nivel 3 | D13: 3 | E13: Días | F13: Saul | G13: 46269 | H13: =IF(OR(C13="Hito",G13="",D13="",E13=""),"",IF(E13="Días",G13+D13-1,IF(E13="Semanas",G13+(D13*7)-1,IF(E13="Meses",EDATE(G13,D13)-1,"")))) -> 46271 | I13: Completado | J13: CC 2.1 | K13: Requisitos no funcionales
... A20: 2.9 | B20: Definir flujo de comunicación con familiares a partir de reportes autorizados | C20: Tarea Nivel 3 | D20: 2 | E20: Días | F20: Saul | G20: 46278 | H20: =IF(OR(C20="Hito",G20="",D20="",E20=""),"",IF(E20="Días",G20+D20-1,IF(E20="Semanas",G20+(D20*7)-1,IF(E20="Meses",EDATE(G20,D20)-1,"")))) -> 46279 | I20: Completado | J20: FC 2.3 | K20: Flujo de comunicación
A21: 2,10 | B21: Elaborar historias de usuario | C21: Tarea Nivel 3 | D21: 3 | E21: Días | F21: Tú | G21: 46280 | H21: =IF(OR(C21="Hito",G21="",D21="",E21=""),"",IF(E21="Días",G21+D21-1,IF(E21="Semanas",G21+(D21*7)-1,IF(E21="Meses",EDATE(G21,D21)-1,"")))) -> 46282 | I21: En Proceso | J21: FC 2.1, 2.3 | K21: Historias de usuario
A22: 2.11 | B22: Definir criterios de aceptación específicos | C22: Tarea Nivel 3 | D22: 2 | E22: Días | F22: Ambos | G22: 46283 | H22: =IF(OR(C22="Hito",G22="",D22="",E22=""),"",IF(E22="Días",G22+D22-1,IF(E22="Semanas",G22+(D22*7)-1,IF(E22="Meses",EDATE(G22,D22)-1,"")))) -> 46284 | I22: En Proceso | J22: FC 2.10 | K22: Criterios de aceptación
A23: 2.12 | B23: Validar requisitos con institución | C23: Tarea Nivel 3 | D23: 2 | E23: Días | F23: Ambos | G23: 46284 | H23: =IF(OR(C23="Hito",G23="",D23="",E23=""),"",IF(E23="Días",G23+D23-1,IF(E23="Semanas",G23+(D23*7)-1,IF(E23="Meses",EDATE(G23,D23)-1,"")))) -> 46285 | I23: Completado | J23: FC 2.11 | K23: Requisitos aprobados
A24: 3 | B24: BASE FUNCIONAL Y GENERACIÓN DE QR | C24: Entregable Nivel 2 | D24: 25 | E24: Días | F24: Ambos | G24: 46286 | H24: =IF(OR(C24="Hito",G24="",D24="",E24=""),"",IF(E24="Días",G24+D24-1,IF(E24="Semanas",G24+(D24*7)-1,IF(E24="Meses",EDATE(G24,D24)-1,"")))) -> 46310 | I24: En Proceso | J24: FC actividades H1 | K24: Sistema QR funcional + códigos validados
A25: 3.1 | B25: Diseñar arquitectura inicial | C25: Tarea Nivel 3 | D25: 2 | E25: Días | F25: Saul | G25: 46287 | H25: =IF(OR(C25="Hito",G25="",D25="",E25=""),"",IF(E25="Días",G25+D25-1,IF(E25="Semanas",G25+(D25*7)-1,IF(E25="Meses",EDATE(G25,D25)-1,"")))) -> 46288 | I25: En Proceso | J25: FC 2.12 | K25: Arquitectura inicial
A26: 3.2 | B26: Diseñar modelo de datos inicial | C26: Tarea Nivel 3 | D26: 2 | E26: Días | F26: Saul | G26: 46287 | H26: =IF(OR(C26="Hito",G26="",D26="",E26=""),"",IF(E26="Días",G26+D26-1,IF(E26="Semanas",G26+(D26*7)-1,IF(E26="Meses",EDATE(G26,D26)-1,"")))) -> 46288 | I26: En Proceso | J26: CC 3.1 | K26: Modelo de datos
A27: 3.3 | B27: Configurar proyecto Next.js/TypeScript | C27: Tarea Nivel 3 | D27: 2 | E27: Días | F27: Saul | G27: 46289 | H27: =IF(OR(C27="Hito",G27="",D27="",E27=""),"",IF(E27="Días",G27+D27-1,IF(E27="Semanas",G27+(D27*7)-1,IF(E27="Meses",EDATE(G27,D27)-1,"")))) -> 46290 | I27: En Proceso | J27: FC 3.1 | K27: Proyecto base
A28: 3.4 | B28: Configurar PostgreSQL | C28: Tarea Nivel 3 | D28: 2 | E28: Días | F28: Saul | G28: 46289 | H28: =IF(OR(C28="Hito",G28="",D28="",E28=""),"",IF(E28="Días",G28+D28-1,IF(E28="Semanas",G28+(D28*7)-1,IF(E28="Meses",EDATE(G28,D28)-1,"")))) -> 46290 | I28: En Proceso | J28: FC 3.2 | K28: BD inicial
A29: 3.5 | B29: Implementar backend/API base | C29: Tarea Nivel 3 | D29: 3 | E29: Días | F29: Saul | G29: 46292 | H29: =IF(OR(C29="Hito",G29="",D29="",E29=""),"",IF(E29="Días",G29+D29-1,IF(E29="Semanas",G29+(D29*7)-1,IF(E29="Meses",EDATE(G29,D29)-1,"")))) -> 46294 | I29: En Proceso | J29: FC 3.3, 3.4 | K29: API base
A30: 3.6 | B30: Implementar modelo de estudiantes | C30: Tarea Nivel 3 | D30: 2 | E30: Días | F30: Saul | G30: 46294 | H30: =IF(OR(C30="Hito",G30="",D30="",E30=""),"",IF(E30="Días",G30+D30-1,IF(E30="Semanas",G30+(D30*7)-1,IF(E30="Meses",EDATE(G30,D30)-1,"")))) -> 46295 | I30: En Proceso | J30: FC 3.4 | K30: Modelo de estudiantes
A31: 3.7 | B31: Implementar CRUD de estudiantes | C31: Tarea Nivel 3 | D31: 3 | E31: Días | F31: Tú | G31: 46295 | H31: =IF(OR(C31="Hito",G31="",D31="",E31=""),"",IF(E31="Días",G31+D31-1,IF(E31="Semanas",G31+(D31*7)-1,IF(E31="Meses",EDATE(G31,D31)-1,"")))) -> 46297 | I31: En Proceso | J31: CC 3.6 | K31: Gestión de estudiantes
A32: 3.8 | B32: Implementar generación de QR | C32: Tarea Nivel 3 | D32: 2 | E32: Días | F32: Saul | G32: 46296 | H32: =IF(OR(C32="Hito",G32="",D32="",E32=""),"",IF(E32="Días",G32+D32-1,IF(E32="Semanas",G32+(D32*7)-1,IF(E32="Meses",EDATE(G32,D32)-1,"")))) -> 46297 | I32: En Proceso | J32: FC 3.6 | K32: Generador QR
A33: 3.9 | B33: Asociar QR con estudiante | C33: Tarea Nivel 3 | D33: 1 | E33: Días | F33: Saul | G33: 46296 | H33: =IF(OR(C33="Hito",G33="",D33="",E33=""),"",IF(E33="Días",G33+D33-1,IF(E33="Semanas",G33+(D33*7)-1,IF(E33="Meses",EDATE(G33,D33)-1,"")))) -> 46296 | I33: En Proceso | J33: FC 3.8 | K33: Asociación QR
... A41: 3.17 | B41: Verificación final de KPI-01 a KPI-06 | C41: Tarea Nivel 3 | D41: 1 | E41: Días | F41: Ambos | G41: 46309 | H41: =IF(OR(C41="Hito",G41="",D41="",E41=""),"",IF(E41="Días",G41+D41-1,IF(E41="Semanas",G41+(D41*7)-1,IF(E41="Meses",EDATE(G41,D41)-1,"")))) -> 46309 | I41: En Proceso | J41: FC 3.16 | K41: Evidencias H01
A42: H01 | B42: HITO 01 — Base funcional y generación de QR | C42: Hito | F42: Ambos | G42: 46310 | I42: No completado | J42: FC H1 | K42: KPI-01 a KPI-06 validados
A43: 4 | B43: SERVIDOR LOCAL E INFRAESTRUCTURA INSTITUCIONAL | C43: Entregable Nivel 2 | D43: 1 | E43: Meses | F43: Ambos | G43: 46312 | H43: =IF(OR(C43="Hito",G43="",D43="",E43=""),"",IF(E43="Días",G43+D43-1,IF(E43="Semanas",G43+(D43*7)-1,IF(E43="Meses",EDATE(G43,D43)-1,"")))) -> 46342 | I43: No Iniciado | K43: Infraestructura local operativa
A44: 4.1 | B44: Levantar especificaciones del equipo servidor | C44: Tarea Nivel 3 | D44: 2 | E44: Días | F44: Saul | G44: 46312 | H44: =IF(OR(C44="Hito",G44="",D44="",E44=""),"",IF(E44="Días",G44+D44-1,IF(E44="Semanas",G44+(D44*7)-1,IF(E44="Meses",EDATE(G44,D44)-1,"")))) -> 46313 | I44: No Iniciado | K44: Especificaciones documentadas
A45: 4.2 | B45: Verificar conectividad de red institucional | C45: Tarea Nivel 3 | D45: 2 | E45: Días | F45: Ambos | G45: 46315 | H45: =IF(OR(C45="Hito",G45="",D45="",E45=""),"",IF(E45="Días",G45+D45-1,IF(E45="Semanas",G45+(D45*7)-1,IF(E45="Meses",EDATE(G45,D45)-1,"")))) -> 46316 | I45: No Iniciado | K45: Conectividad validada
A46: 4.3 | B46: Definir arquitectura de despliegue local | C46: Tarea Nivel 3 | D46: 2 | E46: Días | F46: Saul | G46: 46318 | H46: =IF(OR(C46="Hito",G46="",D46="",E46=""),"",IF(E46="Días",G46+D46-1,IF(E46="Semanas",G46+(D46*7)-1,IF(E46="Meses",EDATE(G46,D46)-1,"")))) -> 46319 | I46: No Iniciado | K46: Arquitectura de despliegue
A47: 4.4 | B47: Preparar sistema operativo del servidor | C47: Tarea Nivel 3 | D47: 2 | E47: Días | F47: Saul | G47: 46318 | H47: =IF(OR(C47="Hito",G47="",D47="",E47=""),"",IF(E47="Días",G47+D47-1,IF(E47="Semanas",G47+(D47*7)-1,IF(E47="Meses",EDATE(G47,D47)-1,"")))) -> 46319 | I47: No Iniciado | K47: Entorno preparado
A48: 4.5 | B48: Configurar PostgreSQL en servidor local | C48: Tarea Nivel 3 | D48: 2 | E48: Días | F48: Saul | G48: 46322 | H48: =IF(OR(C48="Hito",G48="",D48="",E48=""),"",IF(E48="Días",G48+D48-1,IF(E48="Semanas",G48+(D48*7)-1,IF(E48="Meses",EDATE(G48,D48)-1,"")))) -> 46323 | I48: No Iniciado | K48: BD local operativa
A49: 4.6 | B49: Configurar backend/API en servidor | C49: Tarea Nivel 3 | D49: 2 | E49: Días | F49: Saul | G49: 46322 | H49: =IF(OR(C49="Hito",G49="",D49="",E49=""),"",IF(E49="Días",G49+D49-1,IF(E49="Semanas",G49+(D49*7)-1,IF(E49="Meses",EDATE(G49,D49)-1,"")))) -> 46323 | I49: No Iniciado | K49: Backend local operativo
A50: 4.7 | B50: Configurar frontend web para red local | C50: Tarea Nivel 3 | D50: 2 | E50: Días | F50: Tú | G50: 46325 | H50: =IF(OR(C50="Hito",G50="",D50="",E50=""),"",IF(E50="Días",G50+D50-1,IF(E50="Semanas",G50+(D50*7)-1,IF(E50="Meses",EDATE(G50,D50)-1,"")))) -> 46326 | I50: No Iniciado | K50: Web LAN operativa
A51: 4.8 | B51: Integrar aplicación móvil con servidor local | C51: Tarea Nivel 3 | D51: 2 | E51: Días | F51: Ambos | G51: 46326 | H51: =IF(OR(C51="Hito",G51="",D51="",E51=""),"",IF(E51="Días",G51+D51-1,IF(E51="Semanas",G51+(D51*7)-1,IF(E51="Meses",EDATE(G51,D51)-1,"")))) -> 46327 | I51: No Iniciado | K51: App conectada a LAN
A52: 4.9 | B52: Configurar control de acceso al servidor | C52: Tarea Nivel 3 | D52: 1 | E52: Días | F52: Saul | G52: 46329 | H52: =IF(OR(C52="Hito",G52="",D52="",E52=""),"",IF(E52="Días",G52+D52-1,IF(E52="Semanas",G52+(D52*7)-1,IF(E52="Meses",EDATE(G52,D52)-1,"")))) -> 46329 | I52: No Iniciado | K52: Acceso controlado
A53: 4.10 | B53: Configurar respaldos automáticos | C53: Tarea Nivel 3 | D53: 2 | E53: Días | F53: Saul | G53: 46331 | H53: =IF(OR(C53="Hito",G53="",D53="",E53=""),"",IF(E53="Días",G53+D53-1,IF(E53="Semanas",G53+(D53*7)-1,IF(E53="Meses",EDATE(G53,D53)-1,"")))) -> 46332 | I53: No Iniciado | K53: Sistema de respaldos | N53: 46406
...

Sheet Lista de Actividades e Hitos
A1: ID | B1: Actividad/Hito | C1: Entregable Asociado | D1: Fecha Prevista | E1: Responsable | F1: Estado | G1: Tipo
A2: ='Diagrama de Gantt - Estructura '!A2 -> 1 | B2: ='Diagrama de Gantt - Estructura '!B2 -> INICIO Y PLANIFICACIÓN | C2: ='Diagrama de Gantt - Estructura '!K2 -> Base de planificación | D2: ='Diagrama de Gantt - Estructura '!G2 -> 46263 | E2: ='Diagrama de Gantt - Estructura '!F2 -> Ambos | F2: ='Diagrama de Gantt - Estructura '!I2 -> Completado | G2: ='Diagrama de Gantt - Estructura '!C2 -> Entregable Nivel 2
A3: ='Diagrama de Gantt - Estructura '!A3 -> 1.1 | B3: ='Diagrama de Gantt - Estructura '!B3 -> Definir metodología de trabajo | C3: ='Diagrama de Gantt - Estructura '!K3 -> Metodología acordada | D3: ='Diagrama de Gantt - Estructura '!G3 -> 46263 | E3: ='Diagrama de Gantt - Estructura '!F3 -> Tú | F3: ='Diagrama de Gantt - Estructura '!I3 -> Completado | G3: ='Diagrama de Gantt - Estructura '!C3 -> Tarea Nivel 3
A4: ='Diagrama de Gantt - Estructura '!A4 -> 1.2 | B4: ='Diagrama de Gantt - Estructura '!B4 -> Definir herramientas y repositorios | C4: ='Diagrama de Gantt - Estructura '!K4 -> Herramientas configuradas | D4: ='Diagrama de Gantt - Estructura '!G4 -> 46265 | E4: ='Diagrama de Gantt - Estructura '!F4 -> Saul | F4: ='Diagrama de Gantt - Estructura '!I4 -> Completado | G4: ='Diagrama de Gantt - Estructura '!C4 -> Tarea Nivel 3
A5: ='Diagrama de Gantt - Estructura '!A5 -> 1.3 | B5: ='Diagrama de Gantt - Estructura '!B5 -> Elaborar mapa de interesados | C5: ='Diagrama de Gantt - Estructura '!K5 -> Mapa de interesados | D5: ='Diagrama de Gantt - Estructura '!G5 -> 46265 | E5: ='Diagrama de Gantt - Estructura '!F5 -> Tú | F5: ='Diagrama de Gantt - Estructura '!I5 -> Completado | G5: ='Diagrama de Gantt - Estructura '!C5 -> Tarea Nivel 3
A6: ='Diagrama de Gantt - Estructura '!A6 -> 1.4 | B6: ='Diagrama de Gantt - Estructura '!B6 -> Revisar propósito, objetivos y alcance | C6: ='Diagrama de Gantt - Estructura '!K6 -> Alcance validado | D6: ='Diagrama de Gantt - Estructura '!G6 -> 46266 | E6: ='Diagrama de Gantt - Estructura '!F6 -> Ambos | F6: ='Diagrama de Gantt - Estructura '!I6 -> Completado | G6: ='Diagrama de Gantt - Estructura '!C6 -> Tarea Nivel 3
A7: ='Diagrama de Gantt - Estructura '!A7 -> 1.5 | B7: ='Diagrama de Gantt - Estructura '!B7 -> Definir esquema de comunicación del equipo | C7: ='Diagrama de Gantt - Estructura '!K7 -> Esquema de comunicación | D7: ='Diagrama de Gantt - Estructura '!G7 -> 46266 | E7: ='Diagrama de Gantt - Estructura '!F7 -> Saul | F7: ='Diagrama de Gantt - Estructura '!I7 -> Completado | G7: ='Diagrama de Gantt - Estructura '!C7 -> Tarea Nivel 3
A8: ='Diagrama de Gantt - Estructura '!A8 -> 1.6 | B8: ='Diagrama de Gantt - Estructura '!B8 -> Preparar estructura documental del proyecto | C8: ='Diagrama de Gantt - Estructura '!K8 -> Estructura documental | D8: ='Diagrama de Gantt - Estructura '!G8 -> 46267 | E8: ='Diagrama de Gantt - Estructura '!F8 -> Tú | F8: ='Diagrama de Gantt - Estructura '!I8 -> Completado | G8: ='Diagrama de Gantt - Estructura '!C8 -> Tarea Nivel 3
A9: ='Diagrama de Gantt - Estructura '!A9 -> 1.7 | B9: ='Diagrama de Gantt - Estructura '!B9 -> Preparar ambiente inicial de desarrollo | C9: ='Diagrama de Gantt - Estructura '!K9 -> Entorno inicial | D9: ='Diagrama de Gantt - Estructura '!G9 -> 46268 | E9: ='Diagrama de Gantt - Estructura '!F9 -> Saul | F9: ='Diagrama de Gantt - Estructura '!I9 -> Completado | G9: ='Diagrama de Gantt - Estructura '!C9 -> Tarea Nivel 3
A10: ='Diagrama de Gantt - Estructura '!A10 -> 1.8 | B10: ='Diagrama de Gantt - Estructura '!B10 -> Revisión de planificación inicial | C10: ='Diagrama de Gantt - Estructura '!K10 -> Planificación inicial | D10: ='Diagrama de Gantt - Estructura '!G10 -> 46268 | E10: ='Diagrama de Gantt - Estructura '!F10 -> Ambos | F10: ='Diagrama de Gantt - Estructura '!I10 -> Completado | G10: ='Diagrama de Gantt - Estructura '!C10 -> Tarea Nivel 3
A11: ='Diagrama de Gantt - Estructura '!A11 -> 2 | B11: ='Diagrama de Gantt - Estructura '!B11 -> REQUISITOS Y DISEÑO FUNCIONAL | C11: ='Diagrama de Gantt - Estructura '!K11 -> Especificación funcional | D11: ='Diagrama de Gantt - Estructura '!G11 -> 46269 | E11: ='Diagrama de Gantt - Estructura '!F11 -> Ambos | F11: ='Diagrama de Gantt - Estructura '!I11 -> En Proceso | G11: ='Diagrama de Gantt - Estructura '!C11 -> Entregable Nivel 2
A12: ='Diagrama de Gantt - Estructura '!A12 -> 2.1 | B12: ='Diagrama de Gantt - Estructura '!B12 -> Levantamiento de requisitos funcionales | C12: ='Diagrama de Gantt - Estructura '!K12 -> Requisitos funcionales | D12: ='Diagrama de Gantt - Estructura '!G12 -> 46269 | E12: ='Diagrama de Gantt - Estructura '!F12 -> Tú | F12: ='Diagrama de Gantt - Estructura '!I12 -> Completado | G12: ='Diagrama de Gantt - Estructura '!C12 -> Tarea Nivel 3
A13: ='Diagrama de Gantt - Estructura '!A13 -> 2.2 | B13: ='Diagrama de Gantt - Estructura '!B13 -> Levantamiento de requisitos no funcionales | C13: ='Diagrama de Gantt - Estructura '!K13 -> Requisitos no funcionales | D13: ='Diagrama de Gantt - Estructura '!G13 -> 46269 | E13: ='Diagrama de Gantt - Estructura '!F13 -> Saul | F13: ='Diagrama de Gantt - Estructura '!I13 -> Completado | G13: ='Diagrama de Gantt - Estructura '!C13 -> Tarea Nivel 3
... A138: ='Diagrama de Gantt - Estructura '!A138 -> 10.1 | B138: ='Diagrama de Gantt - Estructura '!B138 -> Validar respaldos y recuperación finales | C138: ='Diagrama de Gantt - Estructura '!K138 -> Evidencia final | D138: ='Diagrama de Gantt - Estructura '!G138 -> 46467 | E138: ='Diagrama de Gantt - Estructura '!F138 -> Saul | F138: ='Diagrama de Gantt - Estructura '!I138 -> No Iniciado | G138: ='Diagrama de Gantt - Estructura '!C138 -> Tarea Nivel 3

Sheet Cronología
